<?xml version="1.0"?>
<robot name="robot">

  <!-- materials -->
  <material name="white"><color rgba="1 1 1 1"/></material>
  <material name="orange"><color rgba="1 0.3 0.1 1"/></material>
  <material name="blue"><color rgba="0.2 0.2 1 1"/></material>
  <material name="black"><color rgba="0 0 0 1"/></material>
  <material name="red"><color rgba="1 0 0 1"/></material>
  <material name="green"><color rgba="0 1 0 1"/></material>

  <!-- base -->
  <link name="base_link">
    <inertial>
      <origin xyz="0 0 0" rpy="0 0 0"/>
      <mass value="0.01"/>
      <inertia ixx="0.0000004" ixy="0" ixz="0" iyy="0.0000004" iyz="0" izz="0.0000004"/>
    </inertial>
  </link>

  <joint name="base_footprint_joint" type="fixed">
    <parent link="base_link"/>
    <child link="base_footprint"/>
    <origin xyz="0 0 -0.033" rpy="0 0 0"/>
  </joint>
  <link name="base_footprint"/>

  <!-- chassis -->
  <joint name="chassis_joint" type="fixed">
    <parent link="base_link"/>
    <child link="chassis"/>
    <origin xyz="-0.226 0 -0.01" rpy="0 0 0"/>
  </joint>

  <link name="chassis">
    <visual>
      <origin xyz="0.1675 0 0.069" rpy="0 0 0"/>
      <geometry><box size="0.335 0.265 0.138"/></geometry>
      <material name="red"/>
    </visual>
    <collision>
      <origin xyz="0.1675 0 0.069" rpy="0 0 0"/>
      <geometry><box size="0.335 0.265 0.138"/></geometry>
    </collision>
    <inertial>
      <origin xyz="0.1675 0 0.069" rpy="0 0 0"/>
      <mass value="1.0"/>
      <inertia ixx="0.005564" ixy="0" ixz="0" iyy="0.010744" iyz="0" izz="0.013071"/>
    </inertial>
  </link>
  <gazebo reference="chassis">
    <material>Gazebo/Red</material>
  </gazebo>

  <!-- left wheel -->
  <joint name="left_wheel_joint" type="continuous">
    <parent link="base_link"/>
    <child link="left_wheel"/>
    <origin xyz="0 0.1485 0" rpy="-1.57079632679 0 0"/>
    <axis xyz="0 0 1"/>
  </joint>
  <link name="left_wheel">
    <visual>
      <geometry><cylinder radius="0.033" length="0.026"/></geometry>
      <material name="green"/>
    </visual>
    <collision>
      <geometry><cylinder radius="0.033" length="0.026"/></geometry>
    </collision>
    <inertial>
      <origin xyz="0 0 0" rpy="0 0 0"/>
      <mass value="0.05"/>
      <inertia ixx="0.000018" ixy="0" ixz="0" iyy="0.000018" iyz="0" izz="0.000027"/>
    </inertial>
  </link>
  <gazebo reference="left_wheel">
    <material>Gazebo/Green</material>
    <mu1 value="1.0"/>
    <mu2 value="1.0"/>
  </gazebo>

  <!-- right wheel -->
  <joint name="right_wheel_joint" type="continuous">
    <parent link="base_link"/>
    <child link="right_wheel"/>
    <origin xyz="0 -0.1485 0" rpy="1.57079632679 0 0"/>
    <axis xyz="0 0 -1"/>
  </joint>
  <link name="right_wheel">
    <visual>
      <geometry><cylinder radius="0.033" length="0.026"/></geometry>
      <material name="green"/>
    </visual>
    <collision>
      <geometry><cylinder radius="0.033" length="0.026"/></geometry>
    </collision>
    <inertial>
      <origin xyz="0 0 0" rpy="0 0 0"/>
      <mass value="0.05"/>
      <inertia ixx="0.000018" ixy="0" ixz="0" iyy="0.000018" iyz="0" izz="0.000027"/>
    </inertial>
  </link>
  <gazebo reference="right_wheel">
    <material>Gazebo/Green</material>
    <mu1 value="1.0"/>
    <mu2 value="1.0"/>
  </gazebo>

  <!-- caster wheel -->
  <joint name="caster_wheel_joint" type="fixed">
    <parent link="chassis"/>
    <child link="caster_wheel"/>
    <origin xyz="0.075 0 -0.013" rpy="0 0 0"/>
  </joint>
  <link name="caster_wheel">
    <visual>
      <geometry><sphere radius="0.01"/></geometry>
      <material name="black"/>
    </visual>
    <collision>
      <geometry><sphere radius="0.01"/></geometry>
    </collision>
    <inertial>
      <origin xyz="0 0 0" rpy="0 0 0"/>
      <mass value="0.01"/>
      <inertia ixx="0.0000004" ixy="0" ixz="0" iyy="0.0000004" iyz="0" izz="0.0000004"/>
    </inertial>
  </link>
  <gazebo reference="caster_wheel">
    <material>Gazebo/Black</material>
    <mu1 value="0.2"/>
    <mu2 value="0.2"/>
  </gazebo>

  <!-- lidar -->
  <joint name="laser_joint" type="fixed">
    <parent link="chassis"/>
    <child link="laser_frame"/>
    <origin xyz="0.122 0 0.212" rpy="0 0 0"/>
  </joint>
  <link name="laser_frame">
    <visual>
      <geometry><cylinder radius="0.05" length="0.04"/></geometry>
      <material name="blue"/>
    </visual>
    <visual>
      <origin xyz="0 0 -0.05" rpy="0 0 0"/>
      <geometry><cylinder radius="0.01" length="0.1"/></geometry>
      <material name="blue"/>
    </visual>
    <collision>
      <geometry><cylinder radius="0.05" length="0.04"/></geometry>
    </collision>
    <inertial>
      <origin xyz="0 0 0" rpy="0 0 0"/>
      <mass value="0.1"/>
      <inertia ixx="0.000069" ixy="0" ixz="0" iyy="0.000069" iyz="0" izz="0.000125"/>
    </inertial>
  </link>
  <gazebo reference="laser_frame">
    <material>Gazebo/Blue</material>
    <sensor name="laser" type="ray">
      <pose>0 0 0 0 0 0</pose>
      <visualize>false</visualize>
      <update_rate>10</update_rate>
      <ray>
        <scan>
          <horizontal>
            <samples>360</samples>
            <min_angle>-3.14</min_angle>
            <max_angle>3.14</max_angle>
          </horizontal>
        </scan>
        <range>
          <min>0.3</min>
          <max>12</max>
        </range>
      </ray>
      <plugin name="laser_controller" filename="libgazebo_ros_ray_sensor.so">
        <ros>
          <argument>~/out:=scan</argument>
        </ros>
        <output_type>sensor_msgs/LaserScan</output_type>
        <frame_name>laser_frame</frame_name>
      </plugin>
    </sensor>
  </gazebo>

  <!-- depth camera -->
  <joint name="camera_joint" type="fixed">
    <parent link="chassis"/>
    <child link="camera_link"/>
    <origin xyz="0.305 0 0.15" rpy="0 0 0"/>
  </joint>
  <link name="camera_link">
    <visual>
      <geometry><box size="0.010 0.03 0.03"/></geometry>
      <material name="blue"/>
    </visual>
    <inertial>
      <origin xyz="0 0 0" rpy="0 0 0"/>
      <mass value="0.01"/>
      <inertia ixx="0.000001" ixy="0" ixz="0" iyy="0.000000" iyz="0" izz="0.000000"/>
    </inertial>
  </link>
  <joint name="camera_optical_joint" type="fixed">
    <parent link="camera_link"/>
    <child link="camera_link_optical"/>
    <origin xyz="0 0 0" rpy="-1.57079632679 0 -1.57079632679"/>
  </joint>
  <link name="camera_link_optical"/>

  <gazebo reference="camera_link">
    <material>Gazebo/Red</material>
    <sensor name="camera" type="depth">
      <pose>0 0 0 0 0 0</pose>
      <visualize>true</visualize>
      <update_rate>10</update_rate>
      <camera>
        <horizontal_fov>1.089</horizontal_fov>
        <image>
          <format>R8G8B8</format>
          <width>640</width>
          <height>480</height>
        </image>
        <clip>
          <near>0.05</near>
          <far>8.0</far>
        </clip>
      </camera>
      <plugin name="camera_controller" filename="libgazebo_ros_camera.so">
        <ros>
          <namespace>depth_cam</namespace>
          <remapping>~/image:=color_image</remapping>
          <remapping>~/depth/image:=depth_image</remapping>
          <remapping>~/points:=pointcloud</remapping>
        </ros>
        <frame_name>camera_link_optical</frame_name>
        <min_depth>0.05</min_depth>
        <max_depth>8.0</max_depth>
      </plugin>
    </sensor>
  </gazebo>

  <!-- diff drive plugin -->
  <gazebo>
    <plugin name="diff_drive" filename="libgazebo_ros_diff_drive.so">
      <left_joint>left_wheel_joint</left_joint>
      <right_joint>right_wheel_joint</right_joint>
      <wheel_separation>0.297</wheel_separation>
      <wheel_diameter>0.066</wheel_diameter>
      <max_wheel_torque>200</max_wheel_torque>
      <max_wheel_acceleration>10.0</max_wheel_acceleration>
      <odometry_frame>odom</odometry_frame>
      <robot_base_frame>base_link</robot_base_frame>
      <publish_odom>true</publish_odom>
      <publish_odom_tf>true</publish_odom_tf>
      <publish_wheel_tf>true</publish_wheel_tf>
    </plugin>
  </gazebo>

</robot>

